Workbook

Sheet Summary
A1: Process Quality KPI Report
A3: Recent Reporting Week Start | B3: 46209
A4: Recent Reporting Week End | B4: 46215
A6: Task Type | B6: Team Alpha | C6: Team Beta | D6: Team Gamma | E6: Team Delta | F6: Team Epsilon | G6: Overall
A7: Quality Review | B7: =COUNTIFS('All Data'!$B$2:$B$101,$A54,'All Data'!$E$2:$E$101,">="&$B$3,'All Data'!$E$2:$E$101,"<"&$B$4+1, 'All Data'!$A$2:$A$101,$A$46) -> 3 | C7: =COUNTIFS('All Data'!$B$2:$B$101,$A54,'All Data'!$E$2:$E$101,">="&$B$3,'All Data'!$E$2:$E$101,"<"&$B$4+1, 'All Data'!$A$2:$A$101,$A$47) -> 3 | D7: =COUNTIFS('All Data'!$B$2:$B$101,$A54,'All Data'!$E$2:$E$101,">="&$B$3,'All Data'!$E$2:$E$101,"<"&$B$4+1, 'All Data'!$A$2:$A$101,$A$48) -> 2 | E7: =COUNTIFS('All Data'!$B$2:$B$101,$A54,'All Data'!$E$2:$E$101,">="&$B$3,'All Data'!$E$2:$E$101,"<"&$B$4+1, 'All Data'!$A$2:$A$101,$A$49) -> 4 | F7: =COUNTIFS('All Data'!$B$2:$B$101,$A54,'All Data'!$E$2:$E$101,">="&$B$3,'All Data'!$E$2:$E$101,"<"&$B$4+1, 'All Data'!$A$2:$A$101,$A$50) -> 3 | G7: =sum(B7:F7) -> 15
A8: Complex Case Review | B8: =COUNTIFS('All Data'!$B$2:$B$101,$A55,'All Data'!$E$2:$E$101,">="&$B$3,'All Data'!$E$2:$E$101,"<"&$B$4+1, 'All Data'!$A$2:$A$101,$A$46) -> 3 | C8: =COUNTIFS('All Data'!$B$2:$B$101,$A55,'All Data'!$E$2:$E$101,">="&$B$3,'All Data'!$E$2:$E$101,"<"&$B$4+1, 'All Data'!$A$2:$A$101,$A$47) -> 2 | D8: =COUNTIFS('All Data'!$B$2:$B$101,$A55,'All Data'!$E$2:$E$101,">="&$B$3,'All Data'!$E$2:$E$101,"<"&$B$4+1, 'All Data'!$A$2:$A$101,$A$48) -> 3 | E8: =COUNTIFS('All Data'!$B$2:$B$101,$A55,'All Data'!$E$2:$E$101,">="&$B$3,'All Data'!$E$2:$E$101,"<"&$B$4+1, 'All Data'!$A$2:$A$101,$A$49) -> 3 | F8: =COUNTIFS('All Data'!$B$2:$B$101,$A55,'All Data'!$E$2:$E$101,">="&$B$3,'All Data'!$E$2:$E$101,"<"&$B$4+1, 'All Data'!$A$2:$A$101,$A$50) -> 2 | G8: =sum(B8:F8) -> 13
A9: Process Exception Investigation | B9: =COUNTIFS('All Data'!$B$2:$B$101,$A56,'All Data'!$E$2:$E$101,">="&$B$3,'All Data'!$E$2:$E$101,"<"&$B$4+1, 'All Data'!$A$2:$A$101,$A$46) -> 3 | C9: =COUNTIFS('All Data'!$B$2:$B$101,$A56,'All Data'!$E$2:$E$101,">="&$B$3,'All Data'!$E$2:$E$101,"<"&$B$4+1, 'All Data'!$A$2:$A$101,$A$47) -> 2 | D9: =COUNTIFS('All Data'!$B$2:$B$101,$A56,'All Data'!$E$2:$E$101,">="&$B$3,'All Data'!$E$2:$E$101,"<"&$B$4+1, 'All Data'!$A$2:$A$101,$A$48) -> 2 | E9: =COUNTIFS('All Data'!$B$2:$B$101,$A56,'All Data'!$E$2:$E$101,">="&$B$3,'All Data'!$E$2:$E$101,"<"&$B$4+1, 'All Data'!$A$2:$A$101,$A$49) -> 2 | F9: =COUNTIFS('All Data'!$B$2:$B$101,$A56,'All Data'!$E$2:$E$101,">="&$B$3,'All Data'!$E$2:$E$101,"<"&$B$4+1, 'All Data'!$A$2:$A$101,$A$50) -> 3 | G9: =sum(B9:F9) -> 12
A10: Priority Escalation Review | B10: =COUNTIFS('All Data'!$B$2:$B$101,$A57,'All Data'!$E$2:$E$101,">="&$B$3,'All Data'!$E$2:$E$101,"<"&$B$4+1, 'All Data'!$A$2:$A$101,$A$46) -> 3 | C10: =COUNTIFS('All Data'!$B$2:$B$101,$A57,'All Data'!$E$2:$E$101,">="&$B$3,'All Data'!$E$2:$E$101,"<"&$B$4+1, 'All Data'!$A$2:$A$101,$A$47) -> 4 | D10: =COUNTIFS('All Data'!$B$2:$B$101,$A57,'All Data'!$E$2:$E$101,">="&$B$3,'All Data'!$E$2:$E$101,"<"&$B$4+1, 'All Data'!$A$2:$A$101,$A$48) -> 3 | E10: =COUNTIFS('All Data'!$B$2:$B$101,$A57,'All Data'!$E$2:$E$101,">="&$B$3,'All Data'!$E$2:$E$101,"<"&$B$4+1, 'All Data'!$A$2:$A$101,$A$49) -> 2 | F10: =COUNTIFS('All Data'!$B$2:$B$101,$A57,'All Data'!$E$2:$E$101,">="&$B$3,'All Data'!$E$2:$E$101,"<"&$B$4+1, 'All Data'!$A$2:$A$101,$A$50) -> 4 | G10: =sum(B10:F10) -> 16
A12: SLA | B12: Team Alpha | C12: Team Beta | D12: Team Gamma | E12: Team Delta | F12: Team Epsilon | G12: Overall
A13: Met | B13: =COUNTIFS('All Data'!$E$2:$E$101,">="&$B$3,'All Data'!$E$2:$E$101,"<"&$B$4+1,'All Data'!$F$2:$F$101,"No", 'All Data'!$A$2:$A$101,$A46) -> 2 | C13: =COUNTIFS('All Data'!$E$2:$E$101,">="&$B$3,'All Data'!$E$2:$E$101,"<"&$B$4+1,'All Data'!$F$2:$F$101,"No", 'All Data'!$A$2:$A$101,$A47) -> 3 | D13: =COUNTIFS('All Data'!$E$2:$E$101,">="&$B$3,'All Data'!$E$2:$E$101,"<"&$B$4+1,'All Data'!$F$2:$F$101,"No", 'All Data'!$A$2:$A$101,$A48) -> 2 | E13: =COUNTIFS('All Data'!$E$2:$E$101,">="&$B$3,'All Data'!$E$2:$E$101,"<"&$B$4+1,'All Data'!$F$2:$F$101,"No", 'All Data'!$A$2:$A$101,$A49) -> 1 | F13: =COUNTIFS('All Data'!$E$2:$E$101,">="&$B$3,'All Data'!$E$2:$E$101,"<"&$B$4+1,'All Data'!$F$2:$F$101,"No", 'All Data'!$A$2:$A$101,$A50) -> 3 | G13: =sum(B13:F13) -> 11
A14: Not Met | B14: =COUNTIFS('All Data'!$E$2:$E$101,">="&$B$3,'All Data'!$E$2:$E$101,"<"&$B$4+1,'All Data'!$F$2:$F$101,"Yes", 'All Data'!$A$2:$A$101,$A46) -> 1 | C14: =COUNTIFS('All Data'!$E$2:$E$101,">="&$B$3,'All Data'!$E$2:$E$101,"<"&$B$4+1,'All Data'!$F$2:$F$101,"Yes", 'All Data'!$A$2:$A$101,$A47) -> 1 | D14: =COUNTIFS('All Data'!$E$2:$E$101,">="&$B$3,'All Data'!$E$2:$E$101,"<"&$B$4+1,'All Data'!$F$2:$F$101,"Yes", 'All Data'!$A$2:$A$101,$A48) -> 1 | E14: =COUNTIFS('All Data'!$E$2:$E$101,">="&$B$3,'All Data'!$E$2:$E$101,"<"&$B$4+1,'All Data'!$F$2:$F$101,"Yes", 'All Data'!$A$2:$A$101,$A49) -> 1 | F14: =COUNTIFS('All Data'!$E$2:$E$101,">="&$B$3,'All Data'!$E$2:$E$101,"<"&$B$4+1,'All Data'!$F$2:$F$101,"Yes", 'All Data'!$A$2:$A$101,$A50) -> 1 | G14: =sum(B14:F14) -> 5
A16: Process Quality KPI Report
A18: Older Reporting Week Start | B18: 46202
A19: Older Reporting Week End | B19: 46208
A21: Task Type | B21: Team Alpha | C21: Team Beta | D21: Team Gamma | E21: Team Delta | F21: Team Epsilon | G21: Overall
A22: Quality Review | B22: =COUNTIFS('All Data'!$B$2:$B$101,$A54,'All Data'!$E$2:$E$101,">="&$B$18,'All Data'!$E$2:$E$101,"<"&$B$19+1, 'All Data'!$A$2:$A$101,$A46) -> 2 | C22: =COUNTIFS('All Data'!$B$2:$B$101,$A54,'All Data'!$E$2:$E$101,">="&$B$18,'All Data'!$E$2:$E$101,"<"&$B$19+1, 'All Data'!$A$2:$A$101,$A47) -> 2 | D22: =COUNTIFS('All Data'!$B$2:$B$101,$A54,'All Data'!$E$2:$E$101,">="&$B$18,'All Data'!$E$2:$E$101,"<"&$B$19+1, 'All Data'!$A$2:$A$101,$A48) -> 2 | E22: =COUNTIFS('All Data'!$B$2:$B$101,$A54,'All Data'!$E$2:$E$101,">="&$B$18,'All Data'!$E$2:$E$101,"<"&$B$19+1, 'All Data'!$A$2:$A$101,$A49) -> 3 | F22: =COUNTIFS('All Data'!$B$2:$B$101,$A54,'All Data'!$E$2:$E$101,">="&$B$18,'All Data'!$E$2:$E$101,"<"&$B$19+1, 'All Data'!$A$2:$A$101,$A50) -> 2 | G22: =sum(B22:F22) -> 11
A23: Complex Case Review | B23: =COUNTIFS('All Data'!$B$2:$B$101,$A55,'All Data'!$E$2:$E$101,">="&$B$18,'All Data'!$E$2:$E$101,"<"&$B$19+1, 'All Data'!$A$2:$A$101,$A46) -> 2 | C23: =COUNTIFS('All Data'!$B$2:$B$101,$A55,'All Data'!$E$2:$E$101,">="&$B$18,'All Data'!$E$2:$E$101,"<"&$B$19+1, 'All Data'!$A$2:$A$101,$A47) -> 1 | D23: =COUNTIFS('All Data'!$B$2:$B$101,$A55,'All Data'!$E$2:$E$101,">="&$B$18,'All Data'!$E$2:$E$101,"<"&$B$19+1, 'All Data'!$A$2:$A$101,$A48) -> 2 | E23: =COUNTIFS('All Data'!$B$2:$B$101,$A55,'All Data'!$E$2:$E$101,">="&$B$18,'All Data'!$E$2:$E$101,"<"&$B$19+1, 'All Data'!$A$2:$A$101,$A49) -> 2 | F23: =COUNTIFS('All Data'!$B$2:$B$101,$A55,'All Data'!$E$2:$E$101,">="&$B$18,'All Data'!$E$2:$E$101,"<"&$B$19+1, 'All Data'!$A$2:$A$101,$A50) -> 3 | G23: =sum(B23:F23) -> 10
A24: Process Exception Investigation | B24: =COUNTIFS('All Data'!$B$2:$B$101,$A56,'All Data'!$E$2:$E$101,">="&$B$18,'All Data'!$E$2:$E$101,"<"&$B$19+1, 'All Data'!$A$2:$A$101,$A46) -> 1 | C24: =COUNTIFS('All Data'!$B$2:$B$101,$A56,'All Data'!$E$2:$E$101,">="&$B$18,'All Data'!$E$2:$E$101,"<"&$B$19+1, 'All Data'!$A$2:$A$101,$A47) -> 2 | D24: =COUNTIFS('All Data'!$B$2:$B$101,$A56,'All Data'!$E$2:$E$101,">="&$B$18,'All Data'!$E$2:$E$101,"<"&$B$19+1, 'All Data'!$A$2:$A$101,$A48) -> 2 | E24: =COUNTIFS('All Data'!$B$2:$B$101,$A56,'All Data'!$E$2:$E$101,">="&$B$18,'All Data'!$E$2:$E$101,"<"&$B$19+1, 'All Data'!$A$2:$A$101,$A49) -> 2 | F24: =COUNTIFS('All Data'!$B$2:$B$101,$A56,'All Data'!$E$2:$E$101,">="&$B$18,'All Data'!$E$2:$E$101,"<"&$B$19+1, 'All Data'!$A$2:$A$101,$A50) -> 2 | G24: =sum(B24:F24) -> 9
A25: Priority Escalation Review | B25: =COUNTIFS('All Data'!$B$2:$B$101,$A57,'All Data'!$E$2:$E$101,">="&$B$18,'All Data'!$E$2:$E$101,"<"&$B$19+1, 'All Data'!$A$2:$A$101,$A46) -> 2 | C25: =COUNTIFS('All Data'!$B$2:$B$101,$A57,'All Data'!$E$2:$E$101,">="&$B$18,'All Data'!$E$2:$E$101,"<"&$B$19+1, 'All Data'!$A$2:$A$101,$A47) -> 3 | D25: =COUNTIFS('All Data'!$B$2:$B$101,$A57,'All Data'!$E$2:$E$101,">="&$B$18,'All Data'!$E$2:$E$101,"<"&$B$19+1, 'All Data'!$A$2:$A$101,$A48) -> 3 | E25: =COUNTIFS('All Data'!$B$2:$B$101,$A57,'All Data'!$E$2:$E$101,">="&$B$18,'All Data'!$E$2:$E$101,"<"&$B$19+1, 'All Data'!$A$2:$A$101,$A49) -> 3 | F25: =COUNTIFS('All Data'!$B$2:$B$101,$A57,'All Data'!$E$2:$E$101,">="&$B$18,'All Data'!$E$2:$E$101,"<"&$B$19+1, 'All Data'!$A$2:$A$101,$A50) -> 3 | G25: =sum(B25:F25) -> 14
A27: SLA | B27: Team Alpha | C27: Team Beta | D27: Team Gamma | E27: Team Delta | F27: Team Epsilon | G27: Overall
A28: Met | B28: =COUNTIFS('All Data'!$E$2:$E$101,">="&$B$18,'All Data'!$E$2:$E$101,"<"&$B$19+1,'All Data'!$F$2:$F$101,"No", 'All Data'!$A$2:$A$101,$A46) -> 1 | C28: =COUNTIFS('All Data'!$E$2:$E$101,">="&$B$18,'All Data'!$E$2:$E$101,"<"&$B$19+1,'All Data'!$F$2:$F$101,"No", 'All Data'!$A$2:$A$101,$A47) -> 2 | D28: =COUNTIFS('All Data'!$E$2:$E$101,">="&$B$18,'All Data'!$E$2:$E$101,"<"&$B$19+1,'All Data'!$F$2:$F$101,"No", 'All Data'!$A$2:$A$101,$A48) -> 1 | E28: =COUNTIFS('All Data'!$E$2:$E$101,">="&$B$18,'All Data'!$E$2:$E$101,"<"&$B$19+1,'All Data'!$F$2:$F$101,"No", 'All Data'!$A$2:$A$101,$A49) -> 2 | F28: =COUNTIFS('All Data'!$E$2:$E$101,">="&$B$18,'All Data'!$E$2:$E$101,"<"&$B$19+1,'All Data'!$F$2:$F$101,"No", 'All Data'!$A$2:$A$101,$A50) -> 1 | G28: =sum(B28:F28) -> 7
A29: Not Met | B29: =COUNTIFS('All Data'!$E$2:$E$101,">="&$B$18,'All Data'!$E$2:$E$101,"<"&$B$19+1,'All Data'!$F$2:$F$101,"Yes", 'All Data'!$A$2:$A$101,$A46) -> 1 | C29: =COUNTIFS('All Data'!$E$2:$E$101,">="&$B$18,'All Data'!$E$2:$E$101,"<"&$B$19+1,'All Data'!$F$2:$F$101,"Yes", 'All Data'!$A$2:$A$101,$A47) -> 1 | D29: =COUNTIFS('All Data'!$E$2:$E$101,">="&$B$18,'All Data'!$E$2:$E$101,"<"&$B$19+1,'All Data'!$F$2:$F$101,"Yes", 'All Data'!$A$2:$A$101,$A48) -> 2 | E29: =COUNTIFS('All Data'!$E$2:$E$101,">="&$B$18,'All Data'!$E$2:$E$101,"<"&$B$19+1,'All Data'!$F$2:$F$101,"Yes", 'All Data'!$A$2:$A$101,$A49) -> 1 | F29: =COUNTIFS('All Data'!$E$2:$E$101,">="&$B$18,'All Data'!$E$2:$E$101,"<"&$B$19+1,'All Data'!$F$2:$F$101,"Yes", 'All Data'!$A$2:$A$101,$A50) -> 2 | G29: =sum(B29:F29) -> 7
A31: WoW Comparison
A33: Metric | B33: Older Week | C33: Recent Week | D33: Change | E33: Change %
A34: Total Tasks Completed | B34: =COUNTIFS('All Data'!$E$2:$E$101,">="&$B$18,'All Data'!$E$2:$E$101,"<"&$B$19+1) -> 44 | C34: =COUNTIFS('All Data'!$E$2:$E$101,">="&$B$3,'All Data'!$E$2:$E$101,"<"&$B$4+1) -> 56 | D34: =C34-B34 -> 12 | E34: =IF(B34=0,IF(C34=0,0,1),(C34-B34)/B34) -> 0.27272727
A35: Quality Review | B35: =COUNTIFS('All Data'!$E$2:$E$101,">="&$B$18,'All Data'!$E$2:$E$101,"<"&$B$19+1,'All Data'!$B$2:$B$101,"Quality Review") -> 11 | C35: =COUNTIFS('All Data'!$E$2:$E$101,">="&$B$3,'All Data'!$E$2:$E$101,"<"&$B$4+1,'All Data'!$B$2:$B$101,"Quality Review") -> 15 | D35: =C35-B35 -> 4 | E35: =IF(B35=0,IF(C35=0,0,1),(C35-B35)/B35) -> 0.36363636
A36: Complex Case Review | B36: =COUNTIFS('All Data'!$E$2:$E$101,">="&$B$18,'All Data'!$E$2:$E$101,"<"&$B$19+1,'All Data'!$B$2:$B$101,"Complex Case Review") -> 10 | C36: =COUNTIFS('All Data'!$E$2:$E$101,">="&$B$3,'All Data'!$E$2:$E$101,"<"&$B$4+1,'All Data'!$B$2:$B$101,"Complex Case Review") -> 13 | D36: =C36-B36 -> 3 | E36: =IF(B36=0,IF(C36=0,0,1),(C36-B36)/B36) -> 0.3
A37: Process Exception Investigation | B37: =COUNTIFS('All Data'!$E$2:$E$101,">="&$B$18,'All Data'!$E$2:$E$101,"<"&$B$19+1,'All Data'!$B$2:$B$101,"Process Exception Investigation") -> 9 | C37: =COUNTIFS('All Data'!$E$2:$E$101,">="&$B$3,'All Data'!$E$2:$E$101,"<"&$B$4+1,'All Data'!$B$2:$B$101,"Process Exception Investigation") -> 12 | D37: =C37-B37 -> 3 | E37: =IF(B37=0,IF(C37=0,0,1),(C37-B37)/B37) -> 0.33333333
A38: Priority Escalation Review | B38: =COUNTIFS('All Data'!$E$2:$E$101,">="&$B$18,'All Data'!$E$2:$E$101,"<"&$B$19+1,'All Data'!$B$2:$B$101,"Priority Escalation Review") -> 14 | C38: =COUNTIFS('All Data'!$E$2:$E$101,">="&$B$3,'All Data'!$E$2:$E$101,"<"&$B$4+1,'All Data'!$B$2:$B$101,"Priority Escalation Review") -> 16 | D38: =C38-B38 -> 2 | E38: =IF(B38=0,IF(C38=0,0,1),(C38-B38)/B38) -> 0.14285714
A39: SLA Breaches | B39: =COUNTIFS('All Data'!$E$2:$E$101,">="&$B$18,'All Data'!$E$2:$E$101,"<"&$B$19+1,'All Data'!$F$2:$F$101,"Yes") -> 7 | C39: =COUNTIFS('All Data'!$E$2:$E$101,">="&$B$3,'All Data'!$E$2:$E$101,"<"&$B$4+1,'All Data'!$F$2:$F$101,"Yes") -> 5 | D39: =C39-B39 -> -2 | E39: =IF(B39=0,IF(C39=0,0,1),(C39-B39)/B39) -> -0.28571429
A40: SLA Met | B40: =COUNTIFS('All Data'!$E$2:$E$101,">="&$B$18,'All Data'!$E$2:$E$101,"<"&$B$19+1,'All Data'!$F$2:$F$101,"No") -> 7 | C40: =COUNTIFS('All Data'!$E$2:$E$101,">="&$B$3,'All Data'!$E$2:$E$101,"<"&$B$4+1,'All Data'!$F$2:$F$101,"No") -> 11 | D40: =C40-B40 -> 4 | E40: =IF(B40=0,IF(C40=0,0,1),(C40-B40)/B40) -> 0.57142857
A41: SLA Compliance % | B41: =IF(B38=0,"",B40/B38) -> 0.5 | C41: =IF(C38=0,"",C40/C38) -> 0.6875 | D41: =C41-B41 -> 0.1875 | E41: =""
A42: Priority Escalation Share % | B42: =IF(B34=0,0,B38/B34) -> 0.31818182 | C42: =IF(C34=0,0,C38/C34) -> 0.28571429 | D42: =C42-B42 -> -0.032467532 | E42: =""
A45: Team | B45: Older Tasks | C45: Recent Tasks | D45: WoW Change | E45: WoW Change % | F45: Older SLA % | G45: Recent SLA % | H45: SLA Change
A46: Team Alpha | B46: =COUNTIFS('All Data'!$A$2:$A$101,$A46,'All Data'!$E$2:$E$101,">="&$B$18,'All Data'!$E$2:$E$101,"<"&$B$19+1) -> 7 | C46: =COUNTIFS('All Data'!$A$2:$A$101,$A46,'All Data'!$E$2:$E$101,">="&$B$3,'All Data'!$E$2:$E$101,"<"&$B$4+1) -> 12 | D46: =C46-B46 -> 5 | E46: =IF(B46=0,IF(C46=0,0,1),(C46-B46)/B46) -> 0.71428571 | F46: =IFERROR(COUNTIFS('All Data'!$A$2:$A$101,$A46,'All Data'!$E$2:$E$101,">="&$B$18,'All Data'!$E$2:$E$101,"<"&$B$19+1,'All Data'!$F$2:$F$101,"No")/COUNTIFS('All Data'!$A$2:$A$101,$A46,'All Data'!$E$2:$E$101,">="&$B$18,'All Data'!$E$2:$E$101,"<"&$B$19+1,'All Data'!$B$2:$B$101,"Priority Escalation Review"),"") -> 0.5 | G46: =IFERROR(COUNTIFS('All Data'!$A$2:$A$101,$A46,'All Data'!$E$2:$E$101,">="&$B$3,'All Data'!$E$2:$E$101,"<"&$B$4+1,'All Data'!$F$2:$F$101,"No")/COUNTIFS('All Data'!$A$2:$A$101,$A46,'All Data'!$E$2:$E$101,">="&$B$3,'All Data'!$E$2:$E$101,"<"&$B$4+1,'All Data'!$B$2:$B$101,"Priority Escalation Review"),"") -> 0.66666667 | H46: =IF(OR(F46="",G46=""),"",G46-F46) -> 0.16666667
A47: Team Beta | B47: =COUNTIFS('All Data'!$A$2:$A$101,$A47,'All Data'!$E$2:$E$101,">="&$B$18,'All Data'!$E$2:$E$101,"<"&$B$19+1) -> 8 | C47: =COUNTIFS('All Data'!$A$2:$A$101,$A47,'All Data'!$E$2:$E$101,">="&$B$3,'All Data'!$E$2:$E$101,"<"&$B$4+1) -> 11 | D47: =C47-B47 -> 3 | E47: =IF(B47=0,IF(C47=0,0,1),(C47-B47)/B47) -> 0.375 | F47: =IFERROR(COUNTIFS('All Data'!$A$2:$A$101,$A47,'All Data'!$E$2:$E$101,">="&$B$18,'All Data'!$E$2:$E$101,"<"&$B$19+1,'All Data'!$F$2:$F$101,"No")/COUNTIFS('All Data'!$A$2:$A$101,$A47,'All Data'!$E$2:$E$101,">="&$B$18,'All Data'!$E$2:$E$101,"<"&$B$19+1,'All Data'!$B$2:$B$101,"Priority Escalation Review"),"") -> 0.66666667 | G47: =IFERROR(COUNTIFS('All Data'!$A$2:$A$101,$A47,'All Data'!$E$2:$E$101,">="&$B$3,'All Data'!$E$2:$E$101,"<"&$B$4+1,'All Data'!$F$2:$F$101,"No")/COUNTIFS('All Data'!$A$2:$A$101,$A47,'All Data'!$E$2:$E$101,">="&$B$3,'All Data'!$E$2:$E$101,"<"&$B$4+1,'All Data'!$B$2:$B$101,"Priority Escalation Review"),"") -> 0.75 | H47: =IF(OR(F47="",G47=""),"",G47-F47) -> 0.083333333
A48: Team Gamma | B48: =COUNTIFS('All Data'!$A$2:$A$101,$A48,'All Data'!$E$2:$E$101,">="&$B$18,'All Data'!$E$2:$E$101,"<"&$B$19+1) -> 9 | C48: =COUNTIFS('All Data'!$A$2:$A$101,$A48,'All Data'!$E$2:$E$101,">="&$B$3,'All Data'!$E$2:$E$101,"<"&$B$4+1) -> 10 | D48: =C48-B48 -> 1 | E48: =IF(B48=0,IF(C48=0,0,1),(C48-B48)/B48) -> 0.11111111 | F48: =IFERROR(COUNTIFS('All Data'!$A$2:$A$101,$A48,'All Data'!$E$2:$E$101,">="&$B$18,'All Data'!$E$2:$E$101,"<"&$B$19+1,'All Data'!$F$2:$F$101,"No")/COUNTIFS('All Data'!$A$2:$A$101,$A48,'All Data'!$E$2:$E$101,">="&$B$18,'All Data'!$E$2:$E$101,"<"&$B$19+1,'All Data'!$B$2:$B$101,"Priority Escalation Review"),"") -> 0.33333333 | G48: =IFERROR(COUNTIFS('All Data'!$A$2:$A$101,$A48,'All Data'!$E$2:$E$101,">="&$B$3,'All Data'!$E$2:$E$101,"<"&$B$4+1,'All Data'!$F$2:$F$101,"No")/COUNTIFS('All Data'!$A$2:$A$101,$A48,'All Data'!$E$2:$E$101,">="&$B$3,'All Data'!$E$2:$E$101,"<"&$B$4+1,'All Data'!$B$2:$B$101,"Priority Escalation Review"),"") -> 0.66666667 | H48: =IF(OR(F48="",G48=""),"",G48-F48) -> 0.33333333
A49: Team Delta | B49: =COUNTIFS('All Data'!$A$2:$A$101,$A49,'All Data'!$E$2:$E$101,">="&$B$18,'All Data'!$E$2:$E$101,"<"&$B$19+1) -> 10 | C49: =COUNTIFS('All Data'!$A$2:$A$101,$A49,'All Data'!$E$2:$E$101,">="&$B$3,'All Data'!$E$2:$E$101,"<"&$B$4+1) -> 11 | D49: =C49-B49 -> 1 | E49: =IF(B49=0,IF(C49=0,0,1),(C49-B49)/B49) -> 0.1 | F49: =IFERROR(COUNTIFS('All Data'!$A$2:$A$101,$A49,'All Data'!$E$2:$E$101,">="&$B$18,'All Data'!$E$2:$E$101,"<"&$B$19+1,'All Data'!$F$2:$F$101,"No")/COUNTIFS('All Data'!$A$2:$A$101,$A49,'All Data'!$E$2:$E$101,">="&$B$18,'All Data'!$E$2:$E$101,"<"&$B$19+1,'All Data'!$B$2:$B$101,"Priority Escalation Review"),"") -> 0.66666667 | G49: =IFERROR(COUNTIFS('All Data'!$A$2:$A$101,$A49,'All Data'!$E$2:$E$101,">="&$B$3,'All Data'!$E$2:$E$101,"<"&$B$4+1,'All Data'!$F$2:$F$101,"No")/COUNTIFS('All Data'!$A$2:$A$101,$A49,'All Data'!$E$2:$E$101,">="&$B$3,'All Data'!$E$2:$E$101,"<"&$B$4+1,'All Data'!$B$2:$B$101,"Priority Escalation Review"),"") -> 0.5 | H49: =IF(OR(F49="",G49=""),"",G49-F49) -> -0.16666667
A50: Team Epsilon | B50: =COUNTIFS('All Data'!$A$2:$A$101,$A50,'All Data'!$E$2:$E$101,">="&$B$18,'All Data'!$E$2:$E$101,"<"&$B$19+1) -> 10 | C50: =COUNTIFS('All Data'!$A$2:$A$101,$A50,'All Data'!$E$2:$E$101,">="&$B$3,'All Data'!$E$2:$E$101,"<"&$B$4+1) -> 12 | D50: =C50-B50 -> 2 | E50: =IF(B50=0,IF(C50=0,0,1),(C50-B50)/B50) -> 0.2 | F50: =IFERROR(COUNTIFS('All Data'!$A$2:$A$101,$A50,'All Data'!$E$2:$E$101,">="&$B$18,'All Data'!$E$2:$E$101,"<"&$B$19+1,'All Data'!$F$2:$F$101,"No")/COUNTIFS('All Data'!$A$2:$A$101,$A50,'All Data'!$E$2:$E$101,">="&$B$18,'All Data'!$E$2:$E$101,"<"&$B$19+1,'All Data'!$B$2:$B$101,"Priority Escalation Review"),"") -> 0.33333333 | G50: =IFERROR(COUNTIFS('All Data'!$A$2:$A$101,$A50,'All Data'!$E$2:$E$101,">="&$B$3,'All Data'!$E$2:$E$101,"<"&$B$4+1,'All Data'!$F$2:$F$101,"No")/COUNTIFS('All Data'!$A$2:$A$101,$A50,'All Data'!$E$2:$E$101,">="&$B$3,'All Data'!$E$2:$E$101,"<"&$B$4+1,'All Data'!$B$2:$B$101,"Priority Escalation Review"),"") -> 0.75 | H50: =IF(OR(F50="",G50=""),"",G50-F50) -> 0.41666667
A53: Task Type | B53: Older Tasks | C53: Recent Tasks | D53: WoW Change | E53: WoW Change % | F53: Recent Volume Share
...

Sheet All Data
A1: =IFERROR(__xludf.DUMMYFUNCTION("VSTACK( 'Team Alpha'!A1:F1, FILTER('Team Alpha'!A2:F1000,'Team Alpha'!C2:C1000<>""""), FILTER('Team Beta'!A2:F1000,'Team Beta'!C2:C1000<>""""), FILTER('Team Gamma'!A2:F1000,'Team Gamma'!C2:C1000<>""""), FILTER('Team Delta'!A2:F1000,'Team Delta'!C2:C1000<>"&"""""), FILTER('Team Epsilon'!A2:F1000,'Team Epsilon'!C2:C1000<>"""") )"),"Team") -> Team | B1: =IFERROR(__xludf.DUMMYFUNCTION("""COMPUTED_VALUE"""),"Task Type") -> Task Type | C1: =IFERROR(__xludf.DUMMYFUNCTION("""COMPUTED_VALUE"""),"Task ID") -> Task ID | D1: =IFERROR(__xludf.DUMMYFUNCTION("""COMPUTED_VALUE"""),"Created Date") -> Created Date | E1: =IFERROR(__xludf.DUMMYFUNCTION("""COMPUTED_VALUE"""),"Completed Date") -> Completed Date | F1: =IFERROR(__xludf.DUMMYFUNCTION("""COMPUTED_VALUE"""),"SLA Breached") -> SLA Breached
A2: =IFERROR(__xludf.DUMMYFUNCTION("""COMPUTED_VALUE"""),"Team Alpha") -> Team Alpha | B2: =IFERROR(__xludf.DUMMYFUNCTION("""COMPUTED_VALUE"""),"Quality Review") -> Quality Review | C2: =IFERROR(__xludf.DUMMYFUNCTION("""COMPUTED_VALUE"""),"TASK-2001") -> TASK-2001 | D2: =IFERROR(__xludf.DUMMYFUNCTION("""COMPUTED_VALUE"""),46200.90347222222) -> 46200.903 | E2: =IFERROR(__xludf.DUMMYFUNCTION("""COMPUTED_VALUE"""),46202.57013888889) -> 46202.57 | F2: =IFERROR(__xludf.DUMMYFUNCTION("""COMPUTED_VALUE"""),"N/A") -> N/A
A3: =IFERROR(__xludf.DUMMYFUNCTION("""COMPUTED_VALUE"""),"Team Alpha") -> Team Alpha | B3: =IFERROR(__xludf.DUMMYFUNCTION("""COMPUTED_VALUE"""),"Complex Case Review") -> Complex Case Review | C3: =IFERROR(__xludf.DUMMYFUNCTION("""COMPUTED_VALUE"""),"TASK-2003") -> TASK-2003 | D3: =IFERROR(__xludf.DUMMYFUNCTION("""COMPUTED_VALUE"""),46201.61944444444) -> 46201.619 | E3: =IFERROR(__xludf.DUMMYFUNCTION("""COMPUTED_VALUE"""),46203.66111111111) -> 46203.661 | F3: =IFERROR(__xludf.DUMMYFUNCTION("""COMPUTED_VALUE"""),"N/A") -> N/A
A4: =IFERROR(__xludf.DUMMYFUNCTION("""COMPUTED_VALUE"""),"Team Alpha") -> Team Alpha | B4: =IFERROR(__xludf.DUMMYFUNCTION("""COMPUTED_VALUE"""),"Process Exception Investigation") -> Process Exception Investigation | C4: =IFERROR(__xludf.DUMMYFUNCTION("""COMPUTED_VALUE"""),"TASK-2005") -> TASK-2005 | D4: =IFERROR(__xludf.DUMMYFUNCTION("""COMPUTED_VALUE"""),46201.96041666667) -> 46201.96 | E4: =IFERROR(__xludf.DUMMYFUNCTION("""COMPUTED_VALUE"""),46204.37708333333) -> 46204.377 | F4: =IFERROR(__xludf.DUMMYFUNCTION("""COMPUTED_VALUE"""),"N/A") -> N/A
A5: =IFERROR(__xludf.DUMMYFUNCTION("""COMPUTED_VALUE"""),"Team Alpha") -> Team Alpha | B5: =IFERROR(__xludf.DUMMYFUNCTION("""COMPUTED_VALUE"""),"Priority Escalation Review") -> Priority Escalation Review | C5: =IFERROR(__xludf.DUMMYFUNCTION("""COMPUTED_VALUE"""),"TASK-2006") -> TASK-2006 | D5: =IFERROR(__xludf.DUMMYFUNCTION("""COMPUTED_VALUE"""),46202.67638888889) -> 46202.676 | E5: =IFERROR(__xludf.DUMMYFUNCTION("""COMPUTED_VALUE"""),46205.46805555555) -> 46205.468 | F5: =IFERROR(__xludf.DUMMYFUNCTION("""COMPUTED_VALUE"""),"Yes") -> Yes
A6: =IFERROR(__xludf.DUMMYFUNCTION("""COMPUTED_VALUE"""),"Team Alpha") -> Team Alpha | B6: =IFERROR(__xludf.DUMMYFUNCTION("""COMPUTED_VALUE"""),"Quality Review") -> Quality Review | C6: =IFERROR(__xludf.DUMMYFUNCTION("""COMPUTED_VALUE"""),"TASK-2002") -> TASK-2002 | D6: =IFERROR(__xludf.DUMMYFUNCTION("""COMPUTED_VALUE"""),46203.6625) -> 46203.662 | E6: =IFERROR(__xludf.DUMMYFUNCTION("""COMPUTED_VALUE"""),46205.62083333333) -> 46205.621 | F6: =IFERROR(__xludf.DUMMYFUNCTION("""COMPUTED_VALUE"""),"N/A") -> N/A
A7: =IFERROR(__xludf.DUMMYFUNCTION("""COMPUTED_VALUE"""),"Team Alpha") -> Team Alpha | B7: =IFERROR(__xludf.DUMMYFUNCTION("""COMPUTED_VALUE"""),"Complex Case Review") -> Complex Case Review | C7: =IFERROR(__xludf.DUMMYFUNCTION("""COMPUTED_VALUE"""),"TASK-2004") -> TASK-2004 | D7: =IFERROR(__xludf.DUMMYFUNCTION("""COMPUTED_VALUE"""),46204.33680555555) -> 46204.337 | E7: =IFERROR(__xludf.DUMMYFUNCTION("""COMPUTED_VALUE"""),46206.67013888889) -> 46206.67 | F7: =IFERROR(__xludf.DUMMYFUNCTION("""COMPUTED_VALUE"""),"N/A") -> N/A
A8: =IFERROR(__xludf.DUMMYFUNCTION("""COMPUTED_VALUE"""),"Team Alpha") -> Team Alpha | B8: =IFERROR(__xludf.DUMMYFUNCTION("""COMPUTED_VALUE"""),"Priority Escalation Review") -> Priority Escalation Review | C8: =IFERROR(__xludf.DUMMYFUNCTION("""COMPUTED_VALUE"""),"TASK-2007") -> TASK-2007 | D8: =IFERROR(__xludf.DUMMYFUNCTION("""COMPUTED_VALUE"""),46207.68541666667) -> 46207.685 | E8: =IFERROR(__xludf.DUMMYFUNCTION("""COMPUTED_VALUE"""),46208.51875) -> 46208.519 | F8: =IFERROR(__xludf.DUMMYFUNCTION("""COMPUTED_VALUE"""),"No") -> No
A9: =IFERROR(__xludf.DUMMYFUNCTION("""COMPUTED_VALUE"""),"Team Alpha") -> Team Alpha | B9: =IFERROR(__xludf.DUMMYFUNCTION("""COMPUTED_VALUE"""),"Priority Escalation Review") -> Priority Escalation Review | C9: =IFERROR(__xludf.DUMMYFUNCTION("""COMPUTED_VALUE"""),"TASK-2055") -> TASK-2055 | D9: =IFERROR(__xludf.DUMMYFUNCTION("""COMPUTED_VALUE"""),46208.64444444444) -> 46208.644 | E9: =IFERROR(__xludf.DUMMYFUNCTION("""COMPUTED_VALUE"""),46209.51944444444) -> 46209.519 | F9: =IFERROR(__xludf.DUMMYFUNCTION("""COMPUTED_VALUE"""),"No") -> No
A10: =IFERROR(__xludf.DUMMYFUNCTION("""COMPUTED_VALUE"""),"Team Alpha") -> Team Alpha | B10: =IFERROR(__xludf.DUMMYFUNCTION("""COMPUTED_VALUE"""),"Quality Review") -> Quality Review | C10: =IFERROR(__xludf.DUMMYFUNCTION("""COMPUTED_VALUE"""),"TASK-2047") -> TASK-2047 | D10: =IFERROR(__xludf.DUMMYFUNCTION("""COMPUTED_VALUE"""),46207.33888888889) -> 46207.339 | E10: =IFERROR(__xludf.DUMMYFUNCTION("""COMPUTED_VALUE"""),46209.63055555556) -> 46209.631 | F10: =IFERROR(__xludf.DUMMYFUNCTION("""COMPUTED_VALUE"""),"N/A") -> N/A
A11: =IFERROR(__xludf.DUMMYFUNCTION("""COMPUTED_VALUE"""),"Team Alpha") -> Team Alpha | B11: =IFERROR(__xludf.DUMMYFUNCTION("""COMPUTED_VALUE"""),"Complex Case Review") -> Complex Case Review | C11: =IFERROR(__xludf.DUMMYFUNCTION("""COMPUTED_VALUE"""),"TASK-2050") -> TASK-2050 | D11: =IFERROR(__xludf.DUMMYFUNCTION("""COMPUTED_VALUE"""),46207.72152777778) -> 46207.722 | E11: =IFERROR(__xludf.DUMMYFUNCTION("""COMPUTED_VALUE"""),46210.38819444444) -> 46210.388 | F11: =IFERROR(__xludf.DUMMYFUNCTION("""COMPUTED_VALUE"""),"N/A") -> N/A
A12: =IFERROR(__xludf.DUMMYFUNCTION("""COMPUTED_VALUE"""),"Team Alpha") -> Team Alpha | B12: =IFERROR(__xludf.DUMMYFUNCTION("""COMPUTED_VALUE"""),"Quality Review") -> Quality Review | C12: =IFERROR(__xludf.DUMMYFUNCTION("""COMPUTED_VALUE"""),"TASK-2045") -> TASK-2045 | D12: =IFERROR(__xludf.DUMMYFUNCTION("""COMPUTED_VALUE"""),46208.8625) -> 46208.863 | E12: =IFERROR(__xludf.DUMMYFUNCTION("""COMPUTED_VALUE"""),46210.57083333333) -> 46210.571 | F12: =IFERROR(__xludf.DUMMYFUNCTION("""COMPUTED_VALUE"""),"N/A") -> N/A
A13: =IFERROR(__xludf.DUMMYFUNCTION("""COMPUTED_VALUE"""),"Team Alpha") -> Team Alpha | B13: =IFERROR(__xludf.DUMMYFUNCTION("""COMPUTED_VALUE"""),"Process Exception Investigation") -> Process Exception Investigation | C13: =IFERROR(__xludf.DUMMYFUNCTION("""COMPUTED_VALUE"""),"TASK-2053") -> TASK-2053 | D13: =IFERROR(__xludf.DUMMYFUNCTION("""COMPUTED_VALUE"""),46210.6875) -> 46210.688 | E13: =IFERROR(__xludf.DUMMYFUNCTION("""COMPUTED_VALUE"""),46211.47916666666) -> 46211.479 | F13: =IFERROR(__xludf.DUMMYFUNCTION("""COMPUTED_VALUE"""),"N/A") -> N/A
A14: =IFERROR(__xludf.DUMMYFUNCTION("""COMPUTED_VALUE"""),"Team Alpha") -> Team Alpha | B14: =IFERROR(__xludf.DUMMYFUNCTION("""COMPUTED_VALUE"""),"Complex Case Review") -> Complex Case Review | C14: =IFERROR(__xludf.DUMMYFUNCTION("""COMPUTED_VALUE"""),"TASK-2048") -> TASK-2048 | D14: =IFERROR(__xludf.DUMMYFUNCTION("""COMPUTED_VALUE"""),46209.57847222222) -> 46209.578 | E14: =IFERROR(__xludf.DUMMYFUNCTION("""COMPUTED_VALUE"""),46211.66180555556) -> 46211.662 | F14: =IFERROR(__xludf.DUMMYFUNCTION("""COMPUTED_VALUE"""),"N/A") -> N/A
A15: =IFERROR(__xludf.DUMMYFUNCTION("""COMPUTED_VALUE"""),"Team Alpha") -> Team Alpha | B15: =IFERROR(__xludf.DUMMYFUNCTION("""COMPUTED_VALUE"""),"Process Exception Investigation") -> Process Exception Investigation | C15: =IFERROR(__xludf.DUMMYFUNCTION("""COMPUTED_VALUE"""),"TASK-2051") -> TASK-2051 | D15: =IFERROR(__xludf.DUMMYFUNCTION("""COMPUTED_VALUE"""),46209.91944444444) -> 46209.919 | E15: =IFERROR(__xludf.DUMMYFUNCTION("""COMPUTED_VALUE"""),46212.37777777778) -> 46212.378 | F15: =IFERROR(__xludf.DUMMYFUNCTION("""COMPUTED_VALUE"""),"N/A") -> N/A
A16: =IFERROR(__xludf.DUMMYFUNCTION("""COMPUTED_VALUE"""),"Team Alpha") -> Team Alpha | B16: =IFERROR(__xludf.DUMMYFUNCTION("""COMPUTED_VALUE"""),"Priority Escalation Review") -> Priority Escalation Review | C16: =IFERROR(__xludf.DUMMYFUNCTION("""COMPUTED_VALUE"""),"TASK-2056") -> TASK-2056 | D16: =IFERROR(__xludf.DUMMYFUNCTION("""COMPUTED_VALUE"""),46211.40347222222) -> 46211.403 | E16: =IFERROR(__xludf.DUMMYFUNCTION("""COMPUTED_VALUE"""),46212.57013888889) -> 46212.57 | F16: =IFERROR(__xludf.DUMMYFUNCTION("""COMPUTED_VALUE"""),"No") -> No
A17: =IFERROR(__xludf.DUMMYFUNCTION("""COMPUTED_VALUE"""),"Team Alpha") -> Team Alpha | B17: =IFERROR(__xludf.DUMMYFUNCTION("""COMPUTED_VALUE"""),"Priority Escalation Review") -> Priority Escalation Review | C17: =IFERROR(__xludf.DUMMYFUNCTION("""COMPUTED_VALUE"""),"TASK-2054") -> TASK-2054 | D17: =IFERROR(__xludf.DUMMYFUNCTION("""COMPUTED_VALUE"""),46210.63541666666) -> 46210.635 | E17: =IFERROR(__xludf.DUMMYFUNCTION("""COMPUTED_VALUE"""),46213.46875) -> 46213.469 | F17: =IFERROR(__xludf.DUMMYFUNCTION("""COMPUTED_VALUE"""),"Yes") -> Yes
A18: =IFERROR(__xludf.DUMMYFUNCTION("""COMPUTED_VALUE"""),"Team Alpha") -> Team Alpha | B18: =IFERROR(__xludf.DUMMYFUNCTION("""COMPUTED_VALUE"""),"Quality Review") -> Quality Review | C18: =IFERROR(__xludf.DUMMYFUNCTION("""COMPUTED_VALUE"""),"TASK-2046") -> TASK-2046 | D18: =IFERROR(__xludf.DUMMYFUNCTION("""COMPUTED_VALUE"""),46211.62152777778) -> 46211.622 | E18: =IFERROR(__xludf.DUMMYFUNCTION("""COMPUTED_VALUE"""),46213.62152777778) -> 46213.622 | F18: =IFERROR(__xludf.DUMMYFUNCTION("""COMPUTED_VALUE"""),"N/A") -> N/A
A19: =IFERROR(__xludf.DUMMYFUNCTION("""COMPUTED_VALUE"""),"Team Alpha") -> Team Alpha | B19: =IFERROR(__xludf.DUMMYFUNCTION("""COMPUTED_VALUE"""),"Complex Case Review") -> Complex Case Review | C19: =IFERROR(__xludf.DUMMYFUNCTION("""COMPUTED_VALUE"""),"TASK-2049") -> TASK-2049 | D19: =IFERROR(__xludf.DUMMYFUNCTION("""COMPUTED_VALUE"""),46212.29583333333) -> 46212.296 | E19: =IFERROR(__xludf.DUMMYFUNCTION("""COMPUTED_VALUE"""),46214.67083333333) -> 46214.671 | F19: =IFERROR(__xludf.DUMMYFUNCTION("""COMPUTED_VALUE"""),"N/A") -> N/A
A20: =IFERROR(__xludf.DUMMYFUNCTION("""COMPUTED_VALUE"""),"Team Alpha") -> Team Alpha | B20: =IFERROR(__xludf.DUMMYFUNCTION("""COMPUTED_VALUE"""),"Process Exception Investigation") -> Process Exception Investigation | C20: =IFERROR(__xludf.DUMMYFUNCTION("""COMPUTED_VALUE"""),"TASK-2052") -> TASK-2052 | D20: =IFERROR(__xludf.DUMMYFUNCTION("""COMPUTED_VALUE"""),46212.67847222222) -> 46212.678 | E20: =IFERROR(__xludf.DUMMYFUNCTION("""COMPUTED_VALUE"""),46215.42847222222) -> 46215.428 | F20: =IFERROR(__xludf.DUMMYFUNCTION("""COMPUTED_VALUE"""),"N/A") -> N/A
A21: =IFERROR(__xludf.DUMMYFUNCTION("""COMPUTED_VALUE"""),"Team Beta") -> Team Beta | B21: =IFERROR(__xludf.DUMMYFUNCTION("""COMPUTED_VALUE"""),"Process Exception Investigation") -> Process Exception Investigation | C21: =IFERROR(__xludf.DUMMYFUNCTION("""COMPUTED_VALUE"""),"TASK-2012") -> TASK-2012 | D21: =IFERROR(__xludf.DUMMYFUNCTION("""COMPUTED_VALUE"""),46199.55902777778) -> 46199.559 | E21: =IFERROR(__xludf.DUMMYFUNCTION("""COMPUTED_VALUE"""),46202.47569444445) -> 46202.476 | F21: =IFERROR(__xludf.DUMMYFUNCTION("""COMPUTED_VALUE"""),"N/A") -> N/A
A22: =IFERROR(__xludf.DUMMYFUNCTION("""COMPUTED_VALUE"""),"Team Beta") -> Team Beta | B22: =IFERROR(__xludf.DUMMYFUNCTION("""COMPUTED_VALUE"""),"Priority Escalation Review") -> Priority Escalation Review | C22: =IFERROR(__xludf.DUMMYFUNCTION("""COMPUTED_VALUE"""),"TASK-2014") -> TASK-2014 | D22: =IFERROR(__xludf.DUMMYFUNCTION("""COMPUTED_VALUE"""),46202.525) -> 46202.525 | E22: =IFERROR(__xludf.DUMMYFUNCTION("""COMPUTED_VALUE"""),46203.56666666667) -> 46203.567 | F22: =IFERROR(__xludf.DUMMYFUNCTION("""COMPUTED_VALUE"""),"No") -> No
A23: =IFERROR(__xludf.DUMMYFUNCTION("""COMPUTED_VALUE"""),"Team Beta") -> Team Beta | B23: =IFERROR(__xludf.DUMMYFUNCTION("""COMPUTED_VALUE"""),"Quality Review") -> Quality Review | C23: =IFERROR(__xludf.DUMMYFUNCTION("""COMPUTED_VALUE"""),"TASK-2008") -> TASK-2008 | D23: =IFERROR(__xludf.DUMMYFUNCTION("""COMPUTED_VALUE"""),46202.74305555555) -> 46202.743 | E23: =IFERROR(__xludf.DUMMYFUNCTION("""COMPUTED_VALUE"""),46204.61805555555) -> 46204.618 | F23: =IFERROR(__xludf.DUMMYFUNCTION("""COMPUTED_VALUE"""),"N/A") -> N/A
A24: =IFERROR(__xludf.DUMMYFUNCTION("""COMPUTED_VALUE"""),"Team Beta") -> Team Beta | B24: =IFERROR(__xludf.DUMMYFUNCTION("""COMPUTED_VALUE"""),"Complex Case Review") -> Complex Case Review | C24: =IFERROR(__xludf.DUMMYFUNCTION("""COMPUTED_VALUE"""),"TASK-2010") -> TASK-2010 | D24: =IFERROR(__xludf.DUMMYFUNCTION("""COMPUTED_VALUE"""),46203.41736111111) -> 46203.417 | E24: =IFERROR(__xludf.DUMMYFUNCTION("""COMPUTED_VALUE"""),46205.66736111111) -> 46205.667 | F24: =IFERROR(__xludf.DUMMYFUNCTION("""COMPUTED_VALUE"""),"N/A") -> N/A
A25: =IFERROR(__xludf.DUMMYFUNCTION("""COMPUTED_VALUE"""),"Team Beta") -> Team Beta | B25: =IFERROR(__xludf.DUMMYFUNCTION("""COMPUTED_VALUE"""),"Process Exception Investigation") -> Process Exception Investigation | C25: =IFERROR(__xludf.DUMMYFUNCTION("""COMPUTED_VALUE"""),"TASK-2011") -> TASK-2011 | D25: =IFERROR(__xludf.DUMMYFUNCTION("""COMPUTED_VALUE"""),46203.8) -> 46203.8 | E25: =IFERROR(__xludf.DUMMYFUNCTION("""COMPUTED_VALUE"""),46206.425) -> 46206.425 | F25: =IFERROR(__xludf.DUMMYFUNCTION("""COMPUTED_VALUE"""),"N/A") -> N/A
A26: =IFERROR(__xludf.DUMMYFUNCTION("""COMPUTED_VALUE"""),"Team Beta") -> Team Beta | B26: =IFERROR(__xludf.DUMMYFUNCTION("""COMPUTED_VALUE"""),"Priority Escalation Review") -> Priority Escalation Review | C26: =IFERROR(__xludf.DUMMYFUNCTION("""COMPUTED_VALUE"""),"TASK-2015") -> TASK-2015 | D26: =IFERROR(__xludf.DUMMYFUNCTION("""COMPUTED_VALUE"""),46205.28402777778) -> 46205.284 | E26: =IFERROR(__xludf.DUMMYFUNCTION("""COMPUTED_VALUE"""),46206.61736111111) -> 46206.617 | F26: =IFERROR(__xludf.DUMMYFUNCTION("""COMPUTED_VALUE"""),"No") -> No
A27: =IFERROR(__xludf.DUMMYFUNCTION("""COMPUTED_VALUE"""),"Team Beta") -> Team Beta | B27: =IFERROR(__xludf.DUMMYFUNCTION("""COMPUTED_VALUE"""),"Priority Escalation Review") -> Priority Escalation Review | C27: =IFERROR(__xludf.DUMMYFUNCTION("""COMPUTED_VALUE"""),"TASK-2013") -> TASK-2013 | D27: =IFERROR(__xludf.DUMMYFUNCTION("""COMPUTED_VALUE"""),46206.76597222222) -> 46206.766 | E27: =IFERROR(__xludf.DUMMYFUNCTION("""COMPUTED_VALUE"""),46207.51597222222) -> 46207.516 | F27: =IFERROR(__xludf.DUMMYFUNCTION("""COMPUTED_VALUE"""),"Yes") -> Yes
A28: =IFERROR(__xludf.DUMMYFUNCTION("""COMPUTED_VALUE"""),"Team Beta") -> Team Beta | B28: =IFERROR(__xludf.DUMMYFUNCTION("""COMPUTED_VALUE"""),"Quality Review") -> Quality Review | C28: =IFERROR(__xludf.DUMMYFUNCTION("""COMPUTED_VALUE"""),"TASK-2009") -> TASK-2009 | D28: =IFERROR(__xludf.DUMMYFUNCTION("""COMPUTED_VALUE"""),46205.46041666667) -> 46205.46 | E28: =IFERROR(__xludf.DUMMYFUNCTION("""COMPUTED_VALUE"""),46207.62708333333) -> 46207.627 | F28: =IFERROR(__xludf.DUMMYFUNCTION("""COMPUTED_VALUE"""),"N/A") -> N/A
A29: =IFERROR(__xludf.DUMMYFUNCTION("""COMPUTED_VALUE"""),"Team Beta") -> Team Beta | B29: =IFERROR(__xludf.DUMMYFUNCTION("""COMPUTED_VALUE"""),"Complex Case Review") -> Complex Case Review | C29: =IFERROR(__xludf.DUMMYFUNCTION("""COMPUTED_VALUE"""),"TASK-2061") -> TASK-2061 | D29: =IFERROR(__xludf.DUMMYFUNCTION("""COMPUTED_VALUE"""),46206.80208333334) -> 46206.802 | E29: =IFERROR(__xludf.DUMMYFUNCTION("""COMPUTED_VALUE"""),46209.38541666666) -> 46209.385 | F29: =IFERROR(__xludf.DUMMYFUNCTION("""COMPUTED_VALUE"""),"N/A") -> N/A
A30: =IFERROR(__xludf.DUMMYFUNCTION("""COMPUTED_VALUE"""),"Team Beta") -> Team Beta | B30: =IFERROR(__xludf.DUMMYFUNCTION("""COMPUTED_VALUE"""),"Process Exception Investigation") -> Process Exception Investigation | C30: =IFERROR(__xludf.DUMMYFUNCTION("""COMPUTED_VALUE"""),"TASK-2063") -> TASK-2063 | D30: =IFERROR(__xludf.DUMMYFUNCTION("""COMPUTED_VALUE"""),46207.51805555556) -> 46207.518 | E30: =IFERROR(__xludf.DUMMYFUNCTION("""COMPUTED_VALUE"""),46210.47638888889) -> 46210.476 | F30: =IFERROR(__xludf.DUMMYFUNCTION("""COMPUTED_VALUE"""),"N/A") -> N/A
A31: =IFERROR(__xludf.DUMMYFUNCTION("""COMPUTED_VALUE"""),"Team Beta") -> Team Beta | B31: =IFERROR(__xludf.DUMMYFUNCTION("""COMPUTED_VALUE"""),"Priority Escalation Review") -> Priority Escalation Review | C31: =IFERROR(__xludf.DUMMYFUNCTION("""COMPUTED_VALUE"""),"TASK-2067") -> TASK-2067 | D31: =IFERROR(__xludf.DUMMYFUNCTION("""COMPUTED_VALUE"""),46208.96041666667) -> 46208.96 | E31: =IFERROR(__xludf.DUMMYFUNCTION("""COMPUTED_VALUE"""),46210.62708333333) -> 46210.627 | F31: =IFERROR(__xludf.DUMMYFUNCTION("""COMPUTED_VALUE"""),"No") -> No
A32: =IFERROR(__xludf.DUMMYFUNCTION("""COMPUTED_VALUE"""),"Team Beta") -> Team Beta | B32: =IFERROR(__xludf.DUMMYFUNCTION("""COMPUTED_VALUE"""),"Priority Escalation Review") -> Priority Escalation Review | C32: =IFERROR(__xludf.DUMMYFUNCTION("""COMPUTED_VALUE"""),"TASK-2065") -> TASK-2065 | D32: =IFERROR(__xludf.DUMMYFUNCTION("""COMPUTED_VALUE"""),46210.48402777778) -> 46210.484 | E32: =IFERROR(__xludf.DUMMYFUNCTION("""COMPUTED_VALUE"""),46211.56736111111) -> 46211.567 | F32: =IFERROR(__xludf.DUMMYFUNCTION("""COMPUTED_VALUE"""),"No") -> No
A33: =IFERROR(__xludf.DUMMYFUNCTION("""COMPUTED_VALUE"""),"Team Beta") -> Team Beta | B33: =IFERROR(__xludf.DUMMYFUNCTION("""COMPUTED_VALUE"""),"Quality Review") -> Quality Review | C33: =IFERROR(__xludf.DUMMYFUNCTION("""COMPUTED_VALUE"""),"TASK-2059") -> TASK-2059 | D33: =IFERROR(__xludf.DUMMYFUNCTION("""COMPUTED_VALUE"""),46209.17847222222) -> 46209.178 | E33: =IFERROR(__xludf.DUMMYFUNCTION("""COMPUTED_VALUE"""),46211.67847222222) -> 46211.678 | F33: =IFERROR(__xludf.DUMMYFUNCTION("""COMPUTED_VALUE"""),"N/A") -> N/A
A34: =IFERROR(__xludf.DUMMYFUNCTION("""COMPUTED_VALUE"""),"Team Beta") -> Team Beta | B34: =IFERROR(__xludf.DUMMYFUNCTION("""COMPUTED_VALUE"""),"Quality Review") -> Quality Review | C34: =IFERROR(__xludf.DUMMYFUNCTION("""COMPUTED_VALUE"""),"TASK-2057") -> TASK-2057 | D34: =IFERROR(__xludf.DUMMYFUNCTION("""COMPUTED_VALUE"""),46210.70208333333) -> 46210.702 | E34: =IFERROR(__xludf.DUMMYFUNCTION("""COMPUTED_VALUE"""),46212.61875) -> 46212.619 | F34: =IFERROR(__xludf.DUMMYFUNCTION("""COMPUTED_VALUE"""),"N/A") -> N/A
A35: =IFERROR(__xludf.DUMMYFUNCTION("""COMPUTED_VALUE"""),"Team Beta") -> Team Beta | B35: =IFERROR(__xludf.DUMMYFUNCTION("""COMPUTED_VALUE"""),"Complex Case Review") -> Complex Case Review | C35: =IFERROR(__xludf.DUMMYFUNCTION("""COMPUTED_VALUE"""),"TASK-2060") -> TASK-2060 | D35: =IFERROR(__xludf.DUMMYFUNCTION("""COMPUTED_VALUE"""),46211.37638888889) -> 46211.376 | E35: =IFERROR(__xludf.DUMMYFUNCTION("""COMPUTED_VALUE"""),46213.66805555556) -> 46213.668 | F35: =IFERROR(__xludf.DUMMYFUNCTION("""COMPUTED_VALUE"""),"N/A") -> N/A
A36: =IFERROR(__xludf.DUMMYFUNCTION("""COMPUTED_VALUE"""),"Team Beta") -> Team Beta | B36: =IFERROR(__xludf.DUMMYFUNCTION("""COMPUTED_VALUE"""),"Process Exception Investigation") -> Process Exception Investigation | C36: =IFERROR(__xludf.DUMMYFUNCTION("""COMPUTED_VALUE"""),"TASK-2062") -> TASK-2062 | D36: =IFERROR(__xludf.DUMMYFUNCTION("""COMPUTED_VALUE"""),46211.75902777778) -> 46211.759 | E36: =IFERROR(__xludf.DUMMYFUNCTION("""COMPUTED_VALUE"""),46214.42569444444) -> 46214.426 | F36: =IFERROR(__xludf.DUMMYFUNCTION("""COMPUTED_VALUE"""),"N/A") -> N/A
A37: =IFERROR(__xludf.DUMMYFUNCTION("""COMPUTED_VALUE"""),"Team Beta") -> Team Beta | B37: =IFERROR(__xludf.DUMMYFUNCTION("""COMPUTED_VALUE"""),"Priority Escalation Review") -> Priority Escalation Review | C37: =IFERROR(__xludf.DUMMYFUNCTION("""COMPUTED_VALUE"""),"TASK-2066") -> TASK-2066 | D37: =IFERROR(__xludf.DUMMYFUNCTION("""COMPUTED_VALUE"""),46213.24305555555) -> 46213.243 | E37: =IFERROR(__xludf.DUMMYFUNCTION("""COMPUTED_VALUE"""),46214.61805555555) -> 46214.618 | F37: =IFERROR(__xludf.DUMMYFUNCTION("""COMPUTED_VALUE"""),"No") -> No
A38: =IFERROR(__xludf.DUMMYFUNCTION("""COMPUTED_VALUE"""),"Team Beta") -> Team Beta | B38: =IFERROR(__xludf.DUMMYFUNCTION("""COMPUTED_VALUE"""),"Priority Escalation Review") -> Priority Escalation Review | C38: =IFERROR(__xludf.DUMMYFUNCTION("""COMPUTED_VALUE"""),"TASK-2064") -> TASK-2064 | D38: =IFERROR(__xludf.DUMMYFUNCTION("""COMPUTED_VALUE"""),46214.725) -> 46214.725 | E38: =IFERROR(__xludf.DUMMYFUNCTION("""COMPUTED_VALUE"""),46215.51666666667) -> 46215.517 | F38: =IFERROR(__xludf.DUMMYFUNCTION("""COMPUTED_VALUE"""),"Yes") -> Yes
A39: =IFERROR(__xludf.DUMMYFUNCTION("""COMPUTED_VALUE"""),"Team Beta") -> Team Beta | B39: =IFERROR(__xludf.DUMMYFUNCTION("""COMPUTED_VALUE"""),"Quality Review") -> Quality Review | C39: =IFERROR(__xludf.DUMMYFUNCTION("""COMPUTED_VALUE"""),"TASK-2058") -> TASK-2058 | D39: =IFERROR(__xludf.DUMMYFUNCTION("""COMPUTED_VALUE"""),46213.41944444444) -> 46213.419 | E39: =IFERROR(__xludf.DUMMYFUNCTION("""COMPUTED_VALUE"""),46215.62777777778) -> 46215.628 | F39: =IFERROR(__xludf.DUMMYFUNCTION("""COMPUTED_VALUE"""),"N/A") -> N/A
A40: =IFERROR(__xludf.DUMMYFUNCTION("""COMPUTED_VALUE"""),"Team Gamma") -> Team Gamma | B40: =IFERROR(__xludf.DUMMYFUNCTION("""COMPUTED_VALUE"""),"Priority Escalation Review") -> Priority Escalation Review | C40: =IFERROR(__xludf.DUMMYFUNCTION("""COMPUTED_VALUE"""),"TASK-2022") -> TASK-2022 | D40: =IFERROR(__xludf.DUMMYFUNCTION("""COMPUTED_VALUE"""),46201.60555555556) -> 46201.606 | E40: =IFERROR(__xludf.DUMMYFUNCTION("""COMPUTED_VALUE"""),46202.56388888889) -> 46202.564 | F40: =IFERROR(__xludf.DUMMYFUNCTION("""COMPUTED_VALUE"""),"Yes") -> Yes
...

Sheet Team Alpha
A1: Team | B1: Task Type | C1: Task ID | D1: Created Date | E1: Completed Date | F1: SLA Breached
A2: Team Alpha | B2: Quality Review | C2: TASK-2001 | D2: 46200.903 | E2: 46202.57 | F2: N/A
A3: Team Alpha | B3: Complex Case Review | C3: TASK-2003 | D3: 46201.619 | E3: 46203.661 | F3: N/A
A4: Team Alpha | B4: Process Exception Investigation | C4: TASK-2005 | D4: 46201.96 | E4: 46204.377 | F4: N/A
A5: Team Alpha | B5: Priority Escalation Review | C5: TASK-2006 | D5: 46202.676 | E5: 46205.468 | F5: Yes
A6: Team Alpha | B6: Quality Review | C6: TASK-2002 | D6: 46203.662 | E6: 46205.621 | F6: N/A
A7: Team Alpha | B7: Complex Case Review | C7: TASK-2004 | D7: 46204.337 | E7: 46206.67 | F7: N/A
A8: Team Alpha | B8: Priority Escalation Review | C8: TASK-2007 | D8: 46207.685 | E8: 46208.519 | F8: No
A9: Team Alpha | B9: Priority Escalation Review | C9: TASK-2055 | D9: 46208.644 | E9: 46209.519 | F9: No
A10: Team Alpha | B10: Quality Review | C10: TASK-2047 | D10: 46207.339 | E10: 46209.631 | F10: N/A
A11: Team Alpha | B11: Complex Case Review | C11: TASK-2050 | D11: 46207.722 | E11: 46210.388 | F11: N/A
A12: Team Alpha | B12: Quality Review | C12: TASK-2045 | D12: 46208.863 | E12: 46210.571 | F12: N/A
A13: Team Alpha | B13: Process Exception Investigation | C13: TASK-2053 | D13: 46210.688 | E13: 46211.479 | F13: N/A
... A20: Team Alpha | B20: Process Exception Investigation | C20: TASK-2052 | D20: 46212.678 | E20: 46215.428 | F20: N/A

Sheet Team Beta
A1: Team | B1: Task Type | C1: Task ID | D1: Created Date | E1: Completed Date | F1: SLA Breached
A2: Team Beta | B2: Process Exception Investigation | C2: TASK-2012 | D2: 46199.559 | E2: 46202.476 | F2: N/A
A3: Team Beta | B3: Priority Escalation Review | C3: TASK-2014 | D3: 46202.525 | E3: 46203.567 | F3: No
A4: Team Beta | B4: Quality Review | C4: TASK-2008 | D4: 46202.743 | E4: 46204.618 | F4: N/A
A5: Team Beta | B5: Complex Case Review | C5: TASK-2010 | D5: 46203.417 | E5: 46205.667 | F5: N/A
A6: Team Beta | B6: Process Exception Investigation | C6: TASK-2011 | D6: 46203.8 | E6: 46206.425 | F6: N/A
A7: Team Beta | B7: Priority Escalation Review | C7: TASK-2015 | D7: 46205.284 | E7: 46206.617 | F7: No
A8: Team Beta | B8: Priority Escalation Review | C8: TASK-2013 | D8: 46206.766 | E8: 46207.516 | F8: Yes
A9: Team Beta | B9: Quality Review | C9: TASK-2009 | D9: 46205.46 | E9: 46207.627 | F9: N/A
A10: Team Beta | B10: Complex Case Review | C10: TASK-2061 | D10: 46206.802 | E10: 46209.385 | F10: N/A
A11: Team Beta | B11: Process Exception Investigation | C11: TASK-2063 | D11: 46207.518 | E11: 46210.476 | F11: N/A
A12: Team Beta | B12: Priority Escalation Review | C12: TASK-2067 | D12: 46208.96 | E12: 46210.627 | F12: No
A13: Team Beta | B13: Priority Escalation Review | C13: TASK-2065 | D13: 46210.484 | E13: 46211.567 | F13: No
... A20: Team Beta | B20: Quality Review | C20: TASK-2058 | D20: 46213.419 | E20: 46215.628 | F20: N/A

Sheet Team Gamma
A1: Team | B1: Task Type | C1: Task ID | D1: Created Date | E1: Completed Date | F1: SLA Breached
A2: Team Gamma | B2: Priority Escalation Review | C2: TASK-2022 | D2: 46201.606 | E2: 46202.564 | F2: Yes
A3: Team Gamma | B3: Quality Review | C3: TASK-2017 | D3: 46200.3 | E3: 46202.675 | F3: N/A
A4: Team Gamma | B4: Complex Case Review | C4: TASK-2019 | D4: 46200.683 | E4: 46203.433 | F4: N/A
A5: Team Gamma | B5: Process Exception Investigation | C5: TASK-2021 | D5: 46203.649 | E5: 46204.524 | F5: N/A
A6: Team Gamma | B6: Priority Escalation Review | C6: TASK-2023 | D6: 46204.365 | E6: 46205.615 | F6: Yes
A7: Team Gamma | B7: Quality Review | C7: TASK-2016 | D7: 46204.583 | E7: 46206.666 | F7: N/A
A8: Team Gamma | B8: Complex Case Review | C8: TASK-2018 | D8: 46204.924 | E8: 46207.382 | F8: N/A
A9: Team Gamma | B9: Process Exception Investigation | C9: TASK-2020 | D9: 46205.64 | E9: 46208.473 | F9: N/A
A10: Team Gamma | B10: Priority Escalation Review | C10: TASK-2024 | D10: 46207.124 | E10: 46208.665 | F10: No
A11: Team Gamma | B11: Process Exception Investigation | C11: TASK-2073 | D11: 46206.599 | E11: 46209.474 | F11: N/A
A12: Team Gamma | B12: Priority Escalation Review | C12: TASK-2077 | D12: 46208.083 | E12: 46209.666 | F12: No
A13: Team Gamma | B13: Priority Escalation Review | C13: TASK-2075 | D13: 46209.565 | E13: 46210.565 | F13: Yes
... A20: Team Gamma | B20: Complex Case Review | C20: TASK-2070 | D20: 46212.883 | E20: 46215.383 | F20: N/A

Sheet Team Delta
A1: Team | B1: Task Type | C1: Task ID | D1: Created Date | E1: Completed Date | F1: SLA Breached
A2: Team Delta | B2: Complex Case Review | C2: TASK-2028 | D2: 46199.763 | E2: 46202.43 | F2: N/A
A3: Team Delta | B3: Process Exception Investigation | C3: TASK-2030 | D3: 46202.729 | E3: 46203.521 | F3: N/A
A4: Team Delta | B4: Priority Escalation Review | C4: TASK-2034 | D4: 46201.922 | E4: 46203.672 | F4: No
A5: Team Delta | B5: Quality Review | C5: TASK-2026 | D5: 46201.806 | E5: 46204.39 | F5: N/A
A6: Team Delta | B6: Priority Escalation Review | C6: TASK-2032 | D6: 46203.445 | E6: 46204.612 | F6: Yes
A7: Team Delta | B7: Complex Case Review | C7: TASK-2029 | D7: 46202.522 | E7: 46205.481 | F7: N/A
A8: Team Delta | B8: Process Exception Investigation | C8: TASK-2031 | D8: 46205.488 | E8: 46206.572 | F8: N/A
A9: Team Delta | B9: Quality Review | C9: TASK-2027 | D9: 46204.565 | E9: 46207.44 | F9: N/A
A10: Team Delta | B10: Priority Escalation Review | C10: TASK-2033 | D10: 46206.204 | E10: 46207.662 | F10: No
A11: Team Delta | B11: Quality Review | C11: TASK-2025 | D11: 46206.381 | E11: 46208.672 | F11: N/A
A12: Team Delta | B12: Complex Case Review | C12: TASK-2084 | D12: 46208.49 | E12: 46209.532 | F12: N/A
A13: Team Delta | B13: Quality Review | C13: TASK-2078 | D13: 46207.34 | E13: 46209.673 | F13: N/A
... A22: Team Delta | B22: Priority Escalation Review | C22: TASK-2088 | D22: 46214.163 | E22: 46215.663 | F22: No

Sheet Team Epsilon
A1: Team | B1: Task Type | C1: Task ID | D1: Created Date | E1: Completed Date | F1: SLA Breached
A2: Team Epsilon | B2: Priority Escalation Review | C2: TASK-2043 | D2: 46201.002 | E2: 46202.669 | F2: Yes
A3: Team Epsilon | B3: Quality Review | C3: TASK-2035 | D3: 46200.887 | E3: 46203.387 | F3: N/A
A4: Team Epsilon | B4: Complex Case Review | C4: TASK-2039 | D4: 46202.371 | E4: 46203.579 | F4: N/A
A5: Team Epsilon | B5: Complex Case Review | C5: TASK-2037 | D5: 46201.603 | E5: 46204.478 | F5: N/A
A6: Team Epsilon | B6: Priority Escalation Review | C6: TASK-2044 | D6: 46203.428 | E6: 46205.386 | F6: No
A7: Team Epsilon | B7: Process Exception Investigation | C7: TASK-2040 | D7: 46204.569 | E7: 46205.569 | F7: N/A
A8: Team Epsilon | B8: Quality Review | C8: TASK-2036 | D8: 46203.646 | E8: 46206.438 | F8: N/A
A9: Team Epsilon | B9: Priority Escalation Review | C9: TASK-2042 | D9: 46205.285 | E9: 46206.66 | F9: Yes
A10: Team Epsilon | B10: Complex Case Review | C10: TASK-2038 | D10: 46206.612 | E10: 46207.528 | F10: N/A
A11: Team Epsilon | B11: Process Exception Investigation | C11: TASK-2041 | D11: 46207.328 | E11: 46208.619 | F11: N/A
A12: Team Epsilon | B12: Priority Escalation Review | C12: TASK-2100 | D12: 46207.146 | E12: 46209.438 | F12: No
A13: Team Epsilon | B13: Process Exception Investigation | C13: TASK-2095 | D13: 46208.287 | E13: 46209.62 | F13: N/A
... A23: Team Epsilon | B23: Complex Case Review | C23: TASK-2093 | D23: 46214.571 | E23: 46215.529 | F23: N/A
